{
 "cells": [
  {
   "cell_type": "markdown",
   "id": "92314add",
   "metadata": {},
   "source": [
    "# Interactive request examples "
   ]
  },
  {
   "cell_type": "code",
   "execution_count": 3,
   "id": "1a8edca5",
   "metadata": {},
   "outputs": [],
   "source": [
    "import PIL.Image\n",
    "import sys\n",
    "import io\n",
    "from requests import request"
   ]
  },
  {
   "cell_type": "code",
   "execution_count": 4,
   "id": "b80e912f",
   "metadata": {},
   "outputs": [
    {
     "data": {
      "text/plain": [
       "PIL.JpegImagePlugin.JpegImageFile"
      ]
     },
     "execution_count": 4,
     "metadata": {},
     "output_type": "execute_result"
    }
   ],
   "source": [
    "img = PIL.Image.open('../data/dog.jpg')\n",
    "type(img)"
   ]
  },
  {
   "cell_type": "code",
   "execution_count": 11,
   "id": "240fdaee",
   "metadata": {},
   "outputs": [],
   "source": [
    "img = PIL.Image.open('../data/dog.jpg')\n",
    "buffer = io.BytesIO()\n",
    "img.save(buffer, format='JPEG')\n",
    "with buffer as buf:\n",
    "    buffer.seek(0)\n",
    "    response = request('POST', 'http://localhost:1784/classify', data=buf)\n",
    "out = response.content.decode('utf-8')\n",
    "expected = 'келли, Пембрук, Немецкая овчарка'\n",
    "# self.assertEqual(out, expected)"
   ]
  },
  {
   "cell_type": "code",
   "execution_count": 12,
   "id": "2687d59b",
   "metadata": {},
   "outputs": [
    {
     "data": {
      "text/plain": [
       "'белоголовый орел, куропатка, хартебист'"
      ]
     },
     "execution_count": 12,
     "metadata": {},
     "output_type": "execute_result"
    }
   ],
   "source": [
    "out"
   ]
  },
  {
   "cell_type": "code",
   "execution_count": 13,
   "id": "d9d81da0",
   "metadata": {},
   "outputs": [
    {
     "data": {
      "text/plain": [
       "'келли, Пембрук, Немецкая овчарка'"
      ]
     },
     "execution_count": 13,
     "metadata": {},
     "output_type": "execute_result"
    }
   ],
   "source": [
    "expected"
   ]
  },
  {
   "cell_type": "code",
   "execution_count": 7,
   "id": "91162520",
   "metadata": {},
   "outputs": [
    {
     "ename": "ConnectionError",
     "evalue": "HTTPConnectionPool(host='localhost', port=1784): Max retries exceeded with url: /classify (Caused by NewConnectionError('<urllib3.connection.HTTPConnection object at 0x7fddf355aa60>: Failed to establish a new connection: [Errno 111] Connection refused'))",
     "output_type": "error",
     "traceback": [
      "\u001b[0;31m---------------------------------------------------------------------------\u001b[0m",
      "\u001b[0;31mConnectionRefusedError\u001b[0m                    Traceback (most recent call last)",
      "File \u001b[0;32m~/anaconda3/envs/main/lib/python3.9/site-packages/urllib3/connection.py:174\u001b[0m, in \u001b[0;36mHTTPConnection._new_conn\u001b[0;34m(self)\u001b[0m\n\u001b[1;32m    173\u001b[0m \u001b[38;5;28;01mtry\u001b[39;00m:\n\u001b[0;32m--> 174\u001b[0m     conn \u001b[38;5;241m=\u001b[39m \u001b[43mconnection\u001b[49m\u001b[38;5;241;43m.\u001b[39;49m\u001b[43mcreate_connection\u001b[49m\u001b[43m(\u001b[49m\n\u001b[1;32m    175\u001b[0m \u001b[43m        \u001b[49m\u001b[43m(\u001b[49m\u001b[38;5;28;43mself\u001b[39;49m\u001b[38;5;241;43m.\u001b[39;49m\u001b[43m_dns_host\u001b[49m\u001b[43m,\u001b[49m\u001b[43m \u001b[49m\u001b[38;5;28;43mself\u001b[39;49m\u001b[38;5;241;43m.\u001b[39;49m\u001b[43mport\u001b[49m\u001b[43m)\u001b[49m\u001b[43m,\u001b[49m\u001b[43m \u001b[49m\u001b[38;5;28;43mself\u001b[39;49m\u001b[38;5;241;43m.\u001b[39;49m\u001b[43mtimeout\u001b[49m\u001b[43m,\u001b[49m\u001b[43m \u001b[49m\u001b[38;5;241;43m*\u001b[39;49m\u001b[38;5;241;43m*\u001b[39;49m\u001b[43mextra_kw\u001b[49m\n\u001b[1;32m    176\u001b[0m \u001b[43m    \u001b[49m\u001b[43m)\u001b[49m\n\u001b[1;32m    178\u001b[0m \u001b[38;5;28;01mexcept\u001b[39;00m SocketTimeout:\n",
      "File \u001b[0;32m~/anaconda3/envs/main/lib/python3.9/site-packages/urllib3/util/connection.py:95\u001b[0m, in \u001b[0;36mcreate_connection\u001b[0;34m(address, timeout, source_address, socket_options)\u001b[0m\n\u001b[1;32m     94\u001b[0m \u001b[38;5;28;01mif\u001b[39;00m err \u001b[38;5;129;01mis\u001b[39;00m \u001b[38;5;129;01mnot\u001b[39;00m \u001b[38;5;28;01mNone\u001b[39;00m:\n\u001b[0;32m---> 95\u001b[0m     \u001b[38;5;28;01mraise\u001b[39;00m err\n\u001b[1;32m     97\u001b[0m \u001b[38;5;28;01mraise\u001b[39;00m socket\u001b[38;5;241m.\u001b[39merror(\u001b[38;5;124m\"\u001b[39m\u001b[38;5;124mgetaddrinfo returns an empty list\u001b[39m\u001b[38;5;124m\"\u001b[39m)\n",
      "File \u001b[0;32m~/anaconda3/envs/main/lib/python3.9/site-packages/urllib3/util/connection.py:85\u001b[0m, in \u001b[0;36mcreate_connection\u001b[0;34m(address, timeout, source_address, socket_options)\u001b[0m\n\u001b[1;32m     84\u001b[0m     sock\u001b[38;5;241m.\u001b[39mbind(source_address)\n\u001b[0;32m---> 85\u001b[0m \u001b[43msock\u001b[49m\u001b[38;5;241;43m.\u001b[39;49m\u001b[43mconnect\u001b[49m\u001b[43m(\u001b[49m\u001b[43msa\u001b[49m\u001b[43m)\u001b[49m\n\u001b[1;32m     86\u001b[0m \u001b[38;5;28;01mreturn\u001b[39;00m sock\n",
      "\u001b[0;31mConnectionRefusedError\u001b[0m: [Errno 111] Connection refused",
      "\nDuring handling of the above exception, another exception occurred:\n",
      "\u001b[0;31mNewConnectionError\u001b[0m                        Traceback (most recent call last)",
      "File \u001b[0;32m~/anaconda3/envs/main/lib/python3.9/site-packages/urllib3/connectionpool.py:703\u001b[0m, in \u001b[0;36mHTTPConnectionPool.urlopen\u001b[0;34m(self, method, url, body, headers, retries, redirect, assert_same_host, timeout, pool_timeout, release_conn, chunked, body_pos, **response_kw)\u001b[0m\n\u001b[1;32m    702\u001b[0m \u001b[38;5;66;03m# Make the request on the httplib connection object.\u001b[39;00m\n\u001b[0;32m--> 703\u001b[0m httplib_response \u001b[38;5;241m=\u001b[39m \u001b[38;5;28;43mself\u001b[39;49m\u001b[38;5;241;43m.\u001b[39;49m\u001b[43m_make_request\u001b[49m\u001b[43m(\u001b[49m\n\u001b[1;32m    704\u001b[0m \u001b[43m    \u001b[49m\u001b[43mconn\u001b[49m\u001b[43m,\u001b[49m\n\u001b[1;32m    705\u001b[0m \u001b[43m    \u001b[49m\u001b[43mmethod\u001b[49m\u001b[43m,\u001b[49m\n\u001b[1;32m    706\u001b[0m \u001b[43m    \u001b[49m\u001b[43murl\u001b[49m\u001b[43m,\u001b[49m\n\u001b[1;32m    707\u001b[0m \u001b[43m    \u001b[49m\u001b[43mtimeout\u001b[49m\u001b[38;5;241;43m=\u001b[39;49m\u001b[43mtimeout_obj\u001b[49m\u001b[43m,\u001b[49m\n\u001b[1;32m    708\u001b[0m \u001b[43m    \u001b[49m\u001b[43mbody\u001b[49m\u001b[38;5;241;43m=\u001b[39;49m\u001b[43mbody\u001b[49m\u001b[43m,\u001b[49m\n\u001b[1;32m    709\u001b[0m \u001b[43m    \u001b[49m\u001b[43mheaders\u001b[49m\u001b[38;5;241;43m=\u001b[39;49m\u001b[43mheaders\u001b[49m\u001b[43m,\u001b[49m\n\u001b[1;32m    710\u001b[0m \u001b[43m    \u001b[49m\u001b[43mchunked\u001b[49m\u001b[38;5;241;43m=\u001b[39;49m\u001b[43mchunked\u001b[49m\u001b[43m,\u001b[49m\n\u001b[1;32m    711\u001b[0m \u001b[43m\u001b[49m\u001b[43m)\u001b[49m\n\u001b[1;32m    713\u001b[0m \u001b[38;5;66;03m# If we're going to release the connection in ``finally:``, then\u001b[39;00m\n\u001b[1;32m    714\u001b[0m \u001b[38;5;66;03m# the response doesn't need to know about the connection. Otherwise\u001b[39;00m\n\u001b[1;32m    715\u001b[0m \u001b[38;5;66;03m# it will also try to release it and we'll have a double-release\u001b[39;00m\n\u001b[1;32m    716\u001b[0m \u001b[38;5;66;03m# mess.\u001b[39;00m\n",
      "File \u001b[0;32m~/anaconda3/envs/main/lib/python3.9/site-packages/urllib3/connectionpool.py:398\u001b[0m, in \u001b[0;36mHTTPConnectionPool._make_request\u001b[0;34m(self, conn, method, url, timeout, chunked, **httplib_request_kw)\u001b[0m\n\u001b[1;32m    397\u001b[0m     \u001b[38;5;28;01melse\u001b[39;00m:\n\u001b[0;32m--> 398\u001b[0m         \u001b[43mconn\u001b[49m\u001b[38;5;241;43m.\u001b[39;49m\u001b[43mrequest\u001b[49m\u001b[43m(\u001b[49m\u001b[43mmethod\u001b[49m\u001b[43m,\u001b[49m\u001b[43m \u001b[49m\u001b[43murl\u001b[49m\u001b[43m,\u001b[49m\u001b[43m \u001b[49m\u001b[38;5;241;43m*\u001b[39;49m\u001b[38;5;241;43m*\u001b[39;49m\u001b[43mhttplib_request_kw\u001b[49m\u001b[43m)\u001b[49m\n\u001b[1;32m    400\u001b[0m \u001b[38;5;66;03m# We are swallowing BrokenPipeError (errno.EPIPE) since the server is\u001b[39;00m\n\u001b[1;32m    401\u001b[0m \u001b[38;5;66;03m# legitimately able to close the connection after sending a valid response.\u001b[39;00m\n\u001b[1;32m    402\u001b[0m \u001b[38;5;66;03m# With this behaviour, the received response is still readable.\u001b[39;00m\n",
      "File \u001b[0;32m~/anaconda3/envs/main/lib/python3.9/site-packages/urllib3/connection.py:239\u001b[0m, in \u001b[0;36mHTTPConnection.request\u001b[0;34m(self, method, url, body, headers)\u001b[0m\n\u001b[1;32m    238\u001b[0m     headers[\u001b[38;5;124m\"\u001b[39m\u001b[38;5;124mUser-Agent\u001b[39m\u001b[38;5;124m\"\u001b[39m] \u001b[38;5;241m=\u001b[39m _get_default_user_agent()\n\u001b[0;32m--> 239\u001b[0m \u001b[38;5;28;43msuper\u001b[39;49m\u001b[43m(\u001b[49m\u001b[43mHTTPConnection\u001b[49m\u001b[43m,\u001b[49m\u001b[43m \u001b[49m\u001b[38;5;28;43mself\u001b[39;49m\u001b[43m)\u001b[49m\u001b[38;5;241;43m.\u001b[39;49m\u001b[43mrequest\u001b[49m\u001b[43m(\u001b[49m\u001b[43mmethod\u001b[49m\u001b[43m,\u001b[49m\u001b[43m \u001b[49m\u001b[43murl\u001b[49m\u001b[43m,\u001b[49m\u001b[43m \u001b[49m\u001b[43mbody\u001b[49m\u001b[38;5;241;43m=\u001b[39;49m\u001b[43mbody\u001b[49m\u001b[43m,\u001b[49m\u001b[43m \u001b[49m\u001b[43mheaders\u001b[49m\u001b[38;5;241;43m=\u001b[39;49m\u001b[43mheaders\u001b[49m\u001b[43m)\u001b[49m\n",
      "File \u001b[0;32m~/anaconda3/envs/main/lib/python3.9/http/client.py:1285\u001b[0m, in \u001b[0;36mHTTPConnection.request\u001b[0;34m(self, method, url, body, headers, encode_chunked)\u001b[0m\n\u001b[1;32m   1284\u001b[0m \u001b[38;5;124;03m\"\"\"Send a complete request to the server.\"\"\"\u001b[39;00m\n\u001b[0;32m-> 1285\u001b[0m \u001b[38;5;28;43mself\u001b[39;49m\u001b[38;5;241;43m.\u001b[39;49m\u001b[43m_send_request\u001b[49m\u001b[43m(\u001b[49m\u001b[43mmethod\u001b[49m\u001b[43m,\u001b[49m\u001b[43m \u001b[49m\u001b[43murl\u001b[49m\u001b[43m,\u001b[49m\u001b[43m \u001b[49m\u001b[43mbody\u001b[49m\u001b[43m,\u001b[49m\u001b[43m \u001b[49m\u001b[43mheaders\u001b[49m\u001b[43m,\u001b[49m\u001b[43m \u001b[49m\u001b[43mencode_chunked\u001b[49m\u001b[43m)\u001b[49m\n",
      "File \u001b[0;32m~/anaconda3/envs/main/lib/python3.9/http/client.py:1331\u001b[0m, in \u001b[0;36mHTTPConnection._send_request\u001b[0;34m(self, method, url, body, headers, encode_chunked)\u001b[0m\n\u001b[1;32m   1330\u001b[0m     body \u001b[38;5;241m=\u001b[39m _encode(body, \u001b[38;5;124m'\u001b[39m\u001b[38;5;124mbody\u001b[39m\u001b[38;5;124m'\u001b[39m)\n\u001b[0;32m-> 1331\u001b[0m \u001b[38;5;28;43mself\u001b[39;49m\u001b[38;5;241;43m.\u001b[39;49m\u001b[43mendheaders\u001b[49m\u001b[43m(\u001b[49m\u001b[43mbody\u001b[49m\u001b[43m,\u001b[49m\u001b[43m \u001b[49m\u001b[43mencode_chunked\u001b[49m\u001b[38;5;241;43m=\u001b[39;49m\u001b[43mencode_chunked\u001b[49m\u001b[43m)\u001b[49m\n",
      "File \u001b[0;32m~/anaconda3/envs/main/lib/python3.9/http/client.py:1280\u001b[0m, in \u001b[0;36mHTTPConnection.endheaders\u001b[0;34m(self, message_body, encode_chunked)\u001b[0m\n\u001b[1;32m   1279\u001b[0m     \u001b[38;5;28;01mraise\u001b[39;00m CannotSendHeader()\n\u001b[0;32m-> 1280\u001b[0m \u001b[38;5;28;43mself\u001b[39;49m\u001b[38;5;241;43m.\u001b[39;49m\u001b[43m_send_output\u001b[49m\u001b[43m(\u001b[49m\u001b[43mmessage_body\u001b[49m\u001b[43m,\u001b[49m\u001b[43m \u001b[49m\u001b[43mencode_chunked\u001b[49m\u001b[38;5;241;43m=\u001b[39;49m\u001b[43mencode_chunked\u001b[49m\u001b[43m)\u001b[49m\n",
      "File \u001b[0;32m~/anaconda3/envs/main/lib/python3.9/http/client.py:1040\u001b[0m, in \u001b[0;36mHTTPConnection._send_output\u001b[0;34m(self, message_body, encode_chunked)\u001b[0m\n\u001b[1;32m   1039\u001b[0m \u001b[38;5;28;01mdel\u001b[39;00m \u001b[38;5;28mself\u001b[39m\u001b[38;5;241m.\u001b[39m_buffer[:]\n\u001b[0;32m-> 1040\u001b[0m \u001b[38;5;28;43mself\u001b[39;49m\u001b[38;5;241;43m.\u001b[39;49m\u001b[43msend\u001b[49m\u001b[43m(\u001b[49m\u001b[43mmsg\u001b[49m\u001b[43m)\u001b[49m\n\u001b[1;32m   1042\u001b[0m \u001b[38;5;28;01mif\u001b[39;00m message_body \u001b[38;5;129;01mis\u001b[39;00m \u001b[38;5;129;01mnot\u001b[39;00m \u001b[38;5;28;01mNone\u001b[39;00m:\n\u001b[1;32m   1043\u001b[0m \n\u001b[1;32m   1044\u001b[0m     \u001b[38;5;66;03m# create a consistent interface to message_body\u001b[39;00m\n",
      "File \u001b[0;32m~/anaconda3/envs/main/lib/python3.9/http/client.py:980\u001b[0m, in \u001b[0;36mHTTPConnection.send\u001b[0;34m(self, data)\u001b[0m\n\u001b[1;32m    979\u001b[0m \u001b[38;5;28;01mif\u001b[39;00m \u001b[38;5;28mself\u001b[39m\u001b[38;5;241m.\u001b[39mauto_open:\n\u001b[0;32m--> 980\u001b[0m     \u001b[38;5;28;43mself\u001b[39;49m\u001b[38;5;241;43m.\u001b[39;49m\u001b[43mconnect\u001b[49m\u001b[43m(\u001b[49m\u001b[43m)\u001b[49m\n\u001b[1;32m    981\u001b[0m \u001b[38;5;28;01melse\u001b[39;00m:\n",
      "File \u001b[0;32m~/anaconda3/envs/main/lib/python3.9/site-packages/urllib3/connection.py:205\u001b[0m, in \u001b[0;36mHTTPConnection.connect\u001b[0;34m(self)\u001b[0m\n\u001b[1;32m    204\u001b[0m \u001b[38;5;28;01mdef\u001b[39;00m \u001b[38;5;21mconnect\u001b[39m(\u001b[38;5;28mself\u001b[39m):\n\u001b[0;32m--> 205\u001b[0m     conn \u001b[38;5;241m=\u001b[39m \u001b[38;5;28;43mself\u001b[39;49m\u001b[38;5;241;43m.\u001b[39;49m\u001b[43m_new_conn\u001b[49m\u001b[43m(\u001b[49m\u001b[43m)\u001b[49m\n\u001b[1;32m    206\u001b[0m     \u001b[38;5;28mself\u001b[39m\u001b[38;5;241m.\u001b[39m_prepare_conn(conn)\n",
      "File \u001b[0;32m~/anaconda3/envs/main/lib/python3.9/site-packages/urllib3/connection.py:186\u001b[0m, in \u001b[0;36mHTTPConnection._new_conn\u001b[0;34m(self)\u001b[0m\n\u001b[1;32m    185\u001b[0m \u001b[38;5;28;01mexcept\u001b[39;00m SocketError \u001b[38;5;28;01mas\u001b[39;00m e:\n\u001b[0;32m--> 186\u001b[0m     \u001b[38;5;28;01mraise\u001b[39;00m NewConnectionError(\n\u001b[1;32m    187\u001b[0m         \u001b[38;5;28mself\u001b[39m, \u001b[38;5;124m\"\u001b[39m\u001b[38;5;124mFailed to establish a new connection: \u001b[39m\u001b[38;5;132;01m%s\u001b[39;00m\u001b[38;5;124m\"\u001b[39m \u001b[38;5;241m%\u001b[39m e\n\u001b[1;32m    188\u001b[0m     )\n\u001b[1;32m    190\u001b[0m \u001b[38;5;28;01mreturn\u001b[39;00m conn\n",
      "\u001b[0;31mNewConnectionError\u001b[0m: <urllib3.connection.HTTPConnection object at 0x7fddf355aa60>: Failed to establish a new connection: [Errno 111] Connection refused",
      "\nDuring handling of the above exception, another exception occurred:\n",
      "\u001b[0;31mMaxRetryError\u001b[0m                             Traceback (most recent call last)",
      "File \u001b[0;32m~/anaconda3/envs/main/lib/python3.9/site-packages/requests/adapters.py:489\u001b[0m, in \u001b[0;36mHTTPAdapter.send\u001b[0;34m(self, request, stream, timeout, verify, cert, proxies)\u001b[0m\n\u001b[1;32m    488\u001b[0m \u001b[38;5;28;01mif\u001b[39;00m \u001b[38;5;129;01mnot\u001b[39;00m chunked:\n\u001b[0;32m--> 489\u001b[0m     resp \u001b[38;5;241m=\u001b[39m \u001b[43mconn\u001b[49m\u001b[38;5;241;43m.\u001b[39;49m\u001b[43murlopen\u001b[49m\u001b[43m(\u001b[49m\n\u001b[1;32m    490\u001b[0m \u001b[43m        \u001b[49m\u001b[43mmethod\u001b[49m\u001b[38;5;241;43m=\u001b[39;49m\u001b[43mrequest\u001b[49m\u001b[38;5;241;43m.\u001b[39;49m\u001b[43mmethod\u001b[49m\u001b[43m,\u001b[49m\n\u001b[1;32m    491\u001b[0m \u001b[43m        \u001b[49m\u001b[43murl\u001b[49m\u001b[38;5;241;43m=\u001b[39;49m\u001b[43murl\u001b[49m\u001b[43m,\u001b[49m\n\u001b[1;32m    492\u001b[0m \u001b[43m        \u001b[49m\u001b[43mbody\u001b[49m\u001b[38;5;241;43m=\u001b[39;49m\u001b[43mrequest\u001b[49m\u001b[38;5;241;43m.\u001b[39;49m\u001b[43mbody\u001b[49m\u001b[43m,\u001b[49m\n\u001b[1;32m    493\u001b[0m \u001b[43m        \u001b[49m\u001b[43mheaders\u001b[49m\u001b[38;5;241;43m=\u001b[39;49m\u001b[43mrequest\u001b[49m\u001b[38;5;241;43m.\u001b[39;49m\u001b[43mheaders\u001b[49m\u001b[43m,\u001b[49m\n\u001b[1;32m    494\u001b[0m \u001b[43m        \u001b[49m\u001b[43mredirect\u001b[49m\u001b[38;5;241;43m=\u001b[39;49m\u001b[38;5;28;43;01mFalse\u001b[39;49;00m\u001b[43m,\u001b[49m\n\u001b[1;32m    495\u001b[0m \u001b[43m        \u001b[49m\u001b[43massert_same_host\u001b[49m\u001b[38;5;241;43m=\u001b[39;49m\u001b[38;5;28;43;01mFalse\u001b[39;49;00m\u001b[43m,\u001b[49m\n\u001b[1;32m    496\u001b[0m \u001b[43m        \u001b[49m\u001b[43mpreload_content\u001b[49m\u001b[38;5;241;43m=\u001b[39;49m\u001b[38;5;28;43;01mFalse\u001b[39;49;00m\u001b[43m,\u001b[49m\n\u001b[1;32m    497\u001b[0m \u001b[43m        \u001b[49m\u001b[43mdecode_content\u001b[49m\u001b[38;5;241;43m=\u001b[39;49m\u001b[38;5;28;43;01mFalse\u001b[39;49;00m\u001b[43m,\u001b[49m\n\u001b[1;32m    498\u001b[0m \u001b[43m        \u001b[49m\u001b[43mretries\u001b[49m\u001b[38;5;241;43m=\u001b[39;49m\u001b[38;5;28;43mself\u001b[39;49m\u001b[38;5;241;43m.\u001b[39;49m\u001b[43mmax_retries\u001b[49m\u001b[43m,\u001b[49m\n\u001b[1;32m    499\u001b[0m \u001b[43m        \u001b[49m\u001b[43mtimeout\u001b[49m\u001b[38;5;241;43m=\u001b[39;49m\u001b[43mtimeout\u001b[49m\u001b[43m,\u001b[49m\n\u001b[1;32m    500\u001b[0m \u001b[43m    \u001b[49m\u001b[43m)\u001b[49m\n\u001b[1;32m    502\u001b[0m \u001b[38;5;66;03m# Send the request.\u001b[39;00m\n\u001b[1;32m    503\u001b[0m \u001b[38;5;28;01melse\u001b[39;00m:\n",
      "File \u001b[0;32m~/anaconda3/envs/main/lib/python3.9/site-packages/urllib3/connectionpool.py:787\u001b[0m, in \u001b[0;36mHTTPConnectionPool.urlopen\u001b[0;34m(self, method, url, body, headers, retries, redirect, assert_same_host, timeout, pool_timeout, release_conn, chunked, body_pos, **response_kw)\u001b[0m\n\u001b[1;32m    785\u001b[0m     e \u001b[38;5;241m=\u001b[39m ProtocolError(\u001b[38;5;124m\"\u001b[39m\u001b[38;5;124mConnection aborted.\u001b[39m\u001b[38;5;124m\"\u001b[39m, e)\n\u001b[0;32m--> 787\u001b[0m retries \u001b[38;5;241m=\u001b[39m \u001b[43mretries\u001b[49m\u001b[38;5;241;43m.\u001b[39;49m\u001b[43mincrement\u001b[49m\u001b[43m(\u001b[49m\n\u001b[1;32m    788\u001b[0m \u001b[43m    \u001b[49m\u001b[43mmethod\u001b[49m\u001b[43m,\u001b[49m\u001b[43m \u001b[49m\u001b[43murl\u001b[49m\u001b[43m,\u001b[49m\u001b[43m \u001b[49m\u001b[43merror\u001b[49m\u001b[38;5;241;43m=\u001b[39;49m\u001b[43me\u001b[49m\u001b[43m,\u001b[49m\u001b[43m \u001b[49m\u001b[43m_pool\u001b[49m\u001b[38;5;241;43m=\u001b[39;49m\u001b[38;5;28;43mself\u001b[39;49m\u001b[43m,\u001b[49m\u001b[43m \u001b[49m\u001b[43m_stacktrace\u001b[49m\u001b[38;5;241;43m=\u001b[39;49m\u001b[43msys\u001b[49m\u001b[38;5;241;43m.\u001b[39;49m\u001b[43mexc_info\u001b[49m\u001b[43m(\u001b[49m\u001b[43m)\u001b[49m\u001b[43m[\u001b[49m\u001b[38;5;241;43m2\u001b[39;49m\u001b[43m]\u001b[49m\n\u001b[1;32m    789\u001b[0m \u001b[43m\u001b[49m\u001b[43m)\u001b[49m\n\u001b[1;32m    790\u001b[0m retries\u001b[38;5;241m.\u001b[39msleep()\n",
      "File \u001b[0;32m~/anaconda3/envs/main/lib/python3.9/site-packages/urllib3/util/retry.py:592\u001b[0m, in \u001b[0;36mRetry.increment\u001b[0;34m(self, method, url, response, error, _pool, _stacktrace)\u001b[0m\n\u001b[1;32m    591\u001b[0m \u001b[38;5;28;01mif\u001b[39;00m new_retry\u001b[38;5;241m.\u001b[39mis_exhausted():\n\u001b[0;32m--> 592\u001b[0m     \u001b[38;5;28;01mraise\u001b[39;00m MaxRetryError(_pool, url, error \u001b[38;5;129;01mor\u001b[39;00m ResponseError(cause))\n\u001b[1;32m    594\u001b[0m log\u001b[38;5;241m.\u001b[39mdebug(\u001b[38;5;124m\"\u001b[39m\u001b[38;5;124mIncremented Retry for (url=\u001b[39m\u001b[38;5;124m'\u001b[39m\u001b[38;5;132;01m%s\u001b[39;00m\u001b[38;5;124m'\u001b[39m\u001b[38;5;124m): \u001b[39m\u001b[38;5;132;01m%r\u001b[39;00m\u001b[38;5;124m\"\u001b[39m, url, new_retry)\n",
      "\u001b[0;31mMaxRetryError\u001b[0m: HTTPConnectionPool(host='localhost', port=1784): Max retries exceeded with url: /classify (Caused by NewConnectionError('<urllib3.connection.HTTPConnection object at 0x7fddf355aa60>: Failed to establish a new connection: [Errno 111] Connection refused'))",
      "\nDuring handling of the above exception, another exception occurred:\n",
      "\u001b[0;31mConnectionError\u001b[0m                           Traceback (most recent call last)",
      "Cell \u001b[0;32mIn[7], line 6\u001b[0m\n\u001b[1;32m      4\u001b[0m \u001b[38;5;28;01mwith\u001b[39;00m buffer \u001b[38;5;28;01mas\u001b[39;00m buf:\n\u001b[1;32m      5\u001b[0m     buffer\u001b[38;5;241m.\u001b[39mseek(\u001b[38;5;241m0\u001b[39m)\n\u001b[0;32m----> 6\u001b[0m     response \u001b[38;5;241m=\u001b[39m \u001b[43mrequest\u001b[49m\u001b[43m(\u001b[49m\u001b[38;5;124;43m'\u001b[39;49m\u001b[38;5;124;43mPOST\u001b[39;49m\u001b[38;5;124;43m'\u001b[39;49m\u001b[43m,\u001b[49m\u001b[43m \u001b[49m\u001b[38;5;124;43m'\u001b[39;49m\u001b[38;5;124;43mhttp://localhost:1784/classify\u001b[39;49m\u001b[38;5;124;43m'\u001b[39;49m\u001b[43m,\u001b[49m\u001b[43m \u001b[49m\u001b[43mdata\u001b[49m\u001b[38;5;241;43m=\u001b[39;49m\u001b[43mbuf\u001b[49m\u001b[43m)\u001b[49m\n\u001b[1;32m      8\u001b[0m response\u001b[38;5;241m.\u001b[39mcontent\u001b[38;5;241m.\u001b[39mdecode(\u001b[38;5;124m'\u001b[39m\u001b[38;5;124mutf-8\u001b[39m\u001b[38;5;124m'\u001b[39m)\n",
      "File \u001b[0;32m~/anaconda3/envs/main/lib/python3.9/site-packages/requests/api.py:59\u001b[0m, in \u001b[0;36mrequest\u001b[0;34m(method, url, **kwargs)\u001b[0m\n\u001b[1;32m     55\u001b[0m \u001b[38;5;66;03m# By using the 'with' statement we are sure the session is closed, thus we\u001b[39;00m\n\u001b[1;32m     56\u001b[0m \u001b[38;5;66;03m# avoid leaving sockets open which can trigger a ResourceWarning in some\u001b[39;00m\n\u001b[1;32m     57\u001b[0m \u001b[38;5;66;03m# cases, and look like a memory leak in others.\u001b[39;00m\n\u001b[1;32m     58\u001b[0m \u001b[38;5;28;01mwith\u001b[39;00m sessions\u001b[38;5;241m.\u001b[39mSession() \u001b[38;5;28;01mas\u001b[39;00m session:\n\u001b[0;32m---> 59\u001b[0m     \u001b[38;5;28;01mreturn\u001b[39;00m \u001b[43msession\u001b[49m\u001b[38;5;241;43m.\u001b[39;49m\u001b[43mrequest\u001b[49m\u001b[43m(\u001b[49m\u001b[43mmethod\u001b[49m\u001b[38;5;241;43m=\u001b[39;49m\u001b[43mmethod\u001b[49m\u001b[43m,\u001b[49m\u001b[43m \u001b[49m\u001b[43murl\u001b[49m\u001b[38;5;241;43m=\u001b[39;49m\u001b[43murl\u001b[49m\u001b[43m,\u001b[49m\u001b[43m \u001b[49m\u001b[38;5;241;43m*\u001b[39;49m\u001b[38;5;241;43m*\u001b[39;49m\u001b[43mkwargs\u001b[49m\u001b[43m)\u001b[49m\n",
      "File \u001b[0;32m~/anaconda3/envs/main/lib/python3.9/site-packages/requests/sessions.py:587\u001b[0m, in \u001b[0;36mSession.request\u001b[0;34m(self, method, url, params, data, headers, cookies, files, auth, timeout, allow_redirects, proxies, hooks, stream, verify, cert, json)\u001b[0m\n\u001b[1;32m    582\u001b[0m send_kwargs \u001b[38;5;241m=\u001b[39m {\n\u001b[1;32m    583\u001b[0m     \u001b[38;5;124m\"\u001b[39m\u001b[38;5;124mtimeout\u001b[39m\u001b[38;5;124m\"\u001b[39m: timeout,\n\u001b[1;32m    584\u001b[0m     \u001b[38;5;124m\"\u001b[39m\u001b[38;5;124mallow_redirects\u001b[39m\u001b[38;5;124m\"\u001b[39m: allow_redirects,\n\u001b[1;32m    585\u001b[0m }\n\u001b[1;32m    586\u001b[0m send_kwargs\u001b[38;5;241m.\u001b[39mupdate(settings)\n\u001b[0;32m--> 587\u001b[0m resp \u001b[38;5;241m=\u001b[39m \u001b[38;5;28;43mself\u001b[39;49m\u001b[38;5;241;43m.\u001b[39;49m\u001b[43msend\u001b[49m\u001b[43m(\u001b[49m\u001b[43mprep\u001b[49m\u001b[43m,\u001b[49m\u001b[43m \u001b[49m\u001b[38;5;241;43m*\u001b[39;49m\u001b[38;5;241;43m*\u001b[39;49m\u001b[43msend_kwargs\u001b[49m\u001b[43m)\u001b[49m\n\u001b[1;32m    589\u001b[0m \u001b[38;5;28;01mreturn\u001b[39;00m resp\n",
      "File \u001b[0;32m~/anaconda3/envs/main/lib/python3.9/site-packages/requests/sessions.py:701\u001b[0m, in \u001b[0;36mSession.send\u001b[0;34m(self, request, **kwargs)\u001b[0m\n\u001b[1;32m    698\u001b[0m start \u001b[38;5;241m=\u001b[39m preferred_clock()\n\u001b[1;32m    700\u001b[0m \u001b[38;5;66;03m# Send the request\u001b[39;00m\n\u001b[0;32m--> 701\u001b[0m r \u001b[38;5;241m=\u001b[39m \u001b[43madapter\u001b[49m\u001b[38;5;241;43m.\u001b[39;49m\u001b[43msend\u001b[49m\u001b[43m(\u001b[49m\u001b[43mrequest\u001b[49m\u001b[43m,\u001b[49m\u001b[43m \u001b[49m\u001b[38;5;241;43m*\u001b[39;49m\u001b[38;5;241;43m*\u001b[39;49m\u001b[43mkwargs\u001b[49m\u001b[43m)\u001b[49m\n\u001b[1;32m    703\u001b[0m \u001b[38;5;66;03m# Total elapsed time of the request (approximately)\u001b[39;00m\n\u001b[1;32m    704\u001b[0m elapsed \u001b[38;5;241m=\u001b[39m preferred_clock() \u001b[38;5;241m-\u001b[39m start\n",
      "File \u001b[0;32m~/anaconda3/envs/main/lib/python3.9/site-packages/requests/adapters.py:565\u001b[0m, in \u001b[0;36mHTTPAdapter.send\u001b[0;34m(self, request, stream, timeout, verify, cert, proxies)\u001b[0m\n\u001b[1;32m    561\u001b[0m     \u001b[38;5;28;01mif\u001b[39;00m \u001b[38;5;28misinstance\u001b[39m(e\u001b[38;5;241m.\u001b[39mreason, _SSLError):\n\u001b[1;32m    562\u001b[0m         \u001b[38;5;66;03m# This branch is for urllib3 v1.22 and later.\u001b[39;00m\n\u001b[1;32m    563\u001b[0m         \u001b[38;5;28;01mraise\u001b[39;00m SSLError(e, request\u001b[38;5;241m=\u001b[39mrequest)\n\u001b[0;32m--> 565\u001b[0m     \u001b[38;5;28;01mraise\u001b[39;00m \u001b[38;5;167;01mConnectionError\u001b[39;00m(e, request\u001b[38;5;241m=\u001b[39mrequest)\n\u001b[1;32m    567\u001b[0m \u001b[38;5;28;01mexcept\u001b[39;00m ClosedPoolError \u001b[38;5;28;01mas\u001b[39;00m e:\n\u001b[1;32m    568\u001b[0m     \u001b[38;5;28;01mraise\u001b[39;00m \u001b[38;5;167;01mConnectionError\u001b[39;00m(e, request\u001b[38;5;241m=\u001b[39mrequest)\n",
      "\u001b[0;31mConnectionError\u001b[0m: HTTPConnectionPool(host='localhost', port=1784): Max retries exceeded with url: /classify (Caused by NewConnectionError('<urllib3.connection.HTTPConnection object at 0x7fddf355aa60>: Failed to establish a new connection: [Errno 111] Connection refused'))"
     ]
    }
   ],
   "source": [
    "buffer = io.BytesIO()\n",
    "img.save(buffer, format='JPEG')\n",
    "\n",
    "with buffer as buf:\n",
    "    buffer.seek(0)\n",
    "    response = request('POST', 'http://localhost:1784/classify', data=buf)\n",
    "\n",
    "response.content.decode('utf-8')"
   ]
  },
  {
   "cell_type": "markdown",
   "id": "a02a7395",
   "metadata": {},
   "source": [
    "## Keras model examples"
   ]
  },
  {
   "cell_type": "code",
   "execution_count": 8,
   "id": "02e75f7b",
   "metadata": {},
   "outputs": [],
   "source": [
    "import json\n",
    "import tensorflow as tf\n",
    "import numpy as np"
   ]
  },
  {
   "cell_type": "code",
   "execution_count": 9,
   "id": "cc8b7e05",
   "metadata": {
    "scrolled": true
   },
   "outputs": [
    {
     "name": "stderr",
     "output_type": "stream",
     "text": [
      "2023-06-21 23:07:42.475495: I tensorflow/core/platform/cpu_feature_guard.cc:151] This TensorFlow binary is optimized with oneAPI Deep Neural Network Library (oneDNN) to use the following CPU instructions in performance-critical operations:  SSE4.1 SSE4.2 AVX AVX2 FMA\n",
      "To enable them in other operations, rebuild TensorFlow with the appropriate compiler flags.\n",
      "2023-06-21 23:07:42.477418: I tensorflow/core/common_runtime/process_util.cc:146] Creating new thread pool with default inter op setting: 2. Tune using inter_op_parallelism_threads for best performance.\n"
     ]
    },
    {
     "name": "stdout",
     "output_type": "stream",
     "text": [
      "Downloading data from https://storage.googleapis.com/tensorflow/keras-applications/resnet/resnet101_weights_tf_dim_ordering_tf_kernels.h5\n",
      "179650560/179648224 [==============================] - 8s 0us/step\n",
      "179658752/179648224 [==============================] - 8s 0us/step\n"
     ]
    }
   ],
   "source": [
    "resnet = tf.keras.applications.ResNet101()"
   ]
  },
  {
   "cell_type": "code",
   "execution_count": 10,
   "id": "9abf386b",
   "metadata": {},
   "outputs": [
    {
     "ename": "ValueError",
     "evalue": "Attempt to convert a value (<PIL.JpegImagePlugin.JpegImageFile image mode=RGB size=800x600 at 0x7FDE1C39A7C0>) with an unsupported type (<class 'PIL.JpegImagePlugin.JpegImageFile'>) to a Tensor.",
     "output_type": "error",
     "traceback": [
      "\u001b[0;31m---------------------------------------------------------------------------\u001b[0m",
      "\u001b[0;31mValueError\u001b[0m                                Traceback (most recent call last)",
      "Cell \u001b[0;32mIn[10], line 1\u001b[0m\n\u001b[0;32m----> 1\u001b[0m img_t \u001b[38;5;241m=\u001b[39m \u001b[43mtf\u001b[49m\u001b[38;5;241;43m.\u001b[39;49m\u001b[43mconvert_to_tensor\u001b[49m\u001b[43m(\u001b[49m\n\u001b[1;32m      2\u001b[0m \u001b[43m    \u001b[49m\u001b[43mimg\u001b[49m\u001b[43m,\u001b[49m\u001b[43m \u001b[49m\u001b[43mdtype\u001b[49m\u001b[38;5;241;43m=\u001b[39;49m\u001b[38;5;28;43;01mNone\u001b[39;49;00m\u001b[43m,\u001b[49m\u001b[43m \u001b[49m\u001b[43mdtype_hint\u001b[49m\u001b[38;5;241;43m=\u001b[39;49m\u001b[38;5;28;43;01mNone\u001b[39;49;00m\u001b[43m,\u001b[49m\u001b[43m \u001b[49m\u001b[43mname\u001b[49m\u001b[38;5;241;43m=\u001b[39;49m\u001b[38;5;28;43;01mNone\u001b[39;49;00m\n\u001b[1;32m      3\u001b[0m \u001b[43m)\u001b[49m\n\u001b[1;32m      4\u001b[0m img_t \u001b[38;5;241m=\u001b[39m tf\u001b[38;5;241m.\u001b[39mexpand_dims(img_t, axis\u001b[38;5;241m=\u001b[39m\u001b[38;5;241m0\u001b[39m)\n\u001b[1;32m      5\u001b[0m img_t \u001b[38;5;241m=\u001b[39m tf\u001b[38;5;241m.\u001b[39mimage\u001b[38;5;241m.\u001b[39mresize(img_t, (\u001b[38;5;241m224\u001b[39m, \u001b[38;5;241m224\u001b[39m))\n",
      "File \u001b[0;32m~/anaconda3/envs/main/lib/python3.9/site-packages/tensorflow/python/util/traceback_utils.py:153\u001b[0m, in \u001b[0;36mfilter_traceback.<locals>.error_handler\u001b[0;34m(*args, **kwargs)\u001b[0m\n\u001b[1;32m    151\u001b[0m \u001b[38;5;28;01mexcept\u001b[39;00m \u001b[38;5;167;01mException\u001b[39;00m \u001b[38;5;28;01mas\u001b[39;00m e:\n\u001b[1;32m    152\u001b[0m   filtered_tb \u001b[38;5;241m=\u001b[39m _process_traceback_frames(e\u001b[38;5;241m.\u001b[39m__traceback__)\n\u001b[0;32m--> 153\u001b[0m   \u001b[38;5;28;01mraise\u001b[39;00m e\u001b[38;5;241m.\u001b[39mwith_traceback(filtered_tb) \u001b[38;5;28;01mfrom\u001b[39;00m \u001b[38;5;28mNone\u001b[39m\n\u001b[1;32m    154\u001b[0m \u001b[38;5;28;01mfinally\u001b[39;00m:\n\u001b[1;32m    155\u001b[0m   \u001b[38;5;28;01mdel\u001b[39;00m filtered_tb\n",
      "File \u001b[0;32m~/anaconda3/envs/main/lib/python3.9/site-packages/tensorflow/python/framework/constant_op.py:102\u001b[0m, in \u001b[0;36mconvert_to_eager_tensor\u001b[0;34m(value, ctx, dtype)\u001b[0m\n\u001b[1;32m    100\u001b[0m     dtype \u001b[38;5;241m=\u001b[39m dtypes\u001b[38;5;241m.\u001b[39mas_dtype(dtype)\u001b[38;5;241m.\u001b[39mas_datatype_enum\n\u001b[1;32m    101\u001b[0m ctx\u001b[38;5;241m.\u001b[39mensure_initialized()\n\u001b[0;32m--> 102\u001b[0m \u001b[38;5;28;01mreturn\u001b[39;00m \u001b[43mops\u001b[49m\u001b[38;5;241;43m.\u001b[39;49m\u001b[43mEagerTensor\u001b[49m\u001b[43m(\u001b[49m\u001b[43mvalue\u001b[49m\u001b[43m,\u001b[49m\u001b[43m \u001b[49m\u001b[43mctx\u001b[49m\u001b[38;5;241;43m.\u001b[39;49m\u001b[43mdevice_name\u001b[49m\u001b[43m,\u001b[49m\u001b[43m \u001b[49m\u001b[43mdtype\u001b[49m\u001b[43m)\u001b[49m\n",
      "\u001b[0;31mValueError\u001b[0m: Attempt to convert a value (<PIL.JpegImagePlugin.JpegImageFile image mode=RGB size=800x600 at 0x7FDE1C39A7C0>) with an unsupported type (<class 'PIL.JpegImagePlugin.JpegImageFile'>) to a Tensor."
     ]
    }
   ],
   "source": [
    "img_t = tf.convert_to_tensor(\n",
    "    img, dtype=None, dtype_hint=None, name=None\n",
    ")\n",
    "img_t = tf.expand_dims(img_t, axis=0)\n",
    "img_t = tf.image.resize(img_t, (224, 224))"
   ]
  },
  {
   "cell_type": "code",
   "execution_count": null,
   "id": "d023df66",
   "metadata": {},
   "outputs": [],
   "source": [
    "%%time\n",
    "out = resnet(img_t)"
   ]
  },
  {
   "cell_type": "code",
   "execution_count": null,
   "id": "caa27f78",
   "metadata": {},
   "outputs": [],
   "source": [
    "idxs = tf.argsort(out)[0][:3].numpy()"
   ]
  },
  {
   "cell_type": "code",
   "execution_count": null,
   "id": "d5e3f3ca",
   "metadata": {},
   "outputs": [],
   "source": [
    "with open('../data/imgnet_cats_ru.txt', encoding='utf-8') as f:\n",
    "    cats = f.readlines()\n",
    "\n",
    "cats_ru = [s.rstrip() for s in cats]"
   ]
  },
  {
   "cell_type": "code",
   "execution_count": null,
   "id": "61cce062",
   "metadata": {},
   "outputs": [],
   "source": [
    "[cats_ru[int(i)] for i in idxs]"
   ]
  },
  {
   "cell_type": "code",
   "execution_count": null,
   "id": "9b90d0e4",
   "metadata": {},
   "outputs": [],
   "source": []
  }
 ],
 "metadata": {
  "kernelspec": {
   "display_name": "Python 3 (ipykernel)",
   "language": "python",
   "name": "python3"
  },
  "language_info": {
   "codemirror_mode": {
    "name": "ipython",
    "version": 3
   },
   "file_extension": ".py",
   "mimetype": "text/x-python",
   "name": "python",
   "nbconvert_exporter": "python",
   "pygments_lexer": "ipython3",
   "version": "3.9.16"
  }
 },
 "nbformat": 4,
 "nbformat_minor": 5
}
